Workbook

Sheet README
A1: The Outlook Group — Sales Forecasting & Trendline Analysis: Analysis Workbook
A3: Prepared by: Aishwarya | Outlook Live Project Program — MBA Business Analytics
A5: This workbook is the companion to the forecasting module Word report (Sales_Forecasting_Report.docx).
A6: 'Opening Subs' is treated as monthly new-subscriptions-sold (sales), and 'Expiry' as monthly churn volume —
A7: see the Methodology Notes sheet for why. Outlook Hindi (fortnightly) and Outlook India (weekly) were mapped
A8: to calendar months and summed; all other titles were already monthly. All forecast tables use live formulas
A9: (SUMPRODUCT for the Weighted Moving Average; SLOPE/INTERCEPT/RSQ/FORECAST.LINEAR for the trendline).
A11: Sheet guide:
A12: Methodology Notes - preprocessing assumptions, flow-vs-stock interpretation, method choice rationale.
A13: Monthly Data - the cleaned, reshaped monthly series for all 5 titles + the Outlook Group total.
A14: <Title> Analysis - one sheet per title: WMA table, trendline stats, native chart, insights.
A15: Outlook Group Analysis - the consolidated 5-title total, same structure.
A16: Final Results - all 6 forecasts and recommendations in one place.

Sheet Methodology Notes
B2: Methodology Notes
B4: Source data
B5: Data_for_sales_forecasting_and_trend_line_analysis.xlsx — 5 sheets (Outlook Business, Traveller, Money, Hindi, India), each with 2020/2021/2022 side by side. Business/Traveller/Money report monthly (12 rows); Hindi reports fortnightly (26 rows/year); India reports weekly (52 rows/year). Numbers with Indian comma-grouping (e.g. 7,32,234) were cleaned to plain integers.
B8: Flow vs. stock interpretation
B9: 'Opening Subs' swings sharply period to period (e.g. 732,234 then 639,999 then 1,289,369 in consecutive months for Outlook Business) rather than drifting slowly, which is not how a subscriber-base stock behaves. It was therefore interpreted as a FLOW metric: subscriptions newly opened (sold) in that period — i.e., this is the sales figure the module is asked to forecast. 'Expiry' is the matching churn-volume flow for that period.
B13: Monthly aggregation for Hindi and India
B14: Outlook Hindi's 26 fortnightly issues and Outlook India's 52 weekly issues per year were mapped to calendar months (issue i -> month = CEILING(i * 12 / issues_per_year, 1)) and summed within each month, giving every title a directly comparable series of 36 monthly sales figures (2020-2022).
B18: Forecasting method decision
B19: With only 36 monthly points per title, a machine-learning model (random forest, gradient boosting, LSTM) would be prone to severe overfitting and is not what this task calls for. Two transparent, standard methods were used instead: a 3-month Weighted Moving Average (weights 1:2:3, most recent month weighted highest) for near-term forecasting, and a linear trendline (least-squares regression) for the longer-run growth narrative. Both are extended 3 months forward into Q1 2023.

Sheet Monthly Data
A1: Title | B1: Year | C1: Month | D1: MonthLabel | E1: MonthIndex | F1: Opening Subs (Sales) | G1: Expiry (Churn) | H1: Net Adds | I1: Churn Rate
A2: Outlook Business | B2: 2020 | C2: 1 | D2: Jan-20 | E2: 1 | F2: 732234 | G2: 6454 | H2: =F2-G2 -> 725780 | I2: =G2/F2 -> 0.0088141223
A3: Outlook Business | B3: 2020 | C3: 2 | D3: Feb-20 | E3: 2 | F3: 639999 | G3: 4521 | H3: =F3-G3 -> 635478 | I3: =G3/F3 -> 0.0070640735
A4: Outlook Business | B4: 2020 | C4: 3 | D4: Mar-20 | E4: 3 | F4: 1289369 | G4: 5984 | H4: =F4-G4 -> 1283385 | I4: =G4/F4 -> 0.0046410298
A5: Outlook Business | B5: 2020 | C5: 4 | D5: Apr-20 | E5: 4 | F5: 789213 | G5: 12789 | H5: =F5-G5 -> 776424 | I5: =G5/F5 -> 0.016204751
A6: Outlook Business | B6: 2020 | C6: 5 | D6: May-20 | E6: 5 | F6: 1558639 | G6: 9235 | H6: =F6-G6 -> 1549404 | I6: =G6/F6 -> 0.005925041
A7: Outlook Business | B7: 2020 | C7: 6 | D7: Jun-20 | E7: 6 | F7: 1758963 | G7: 18965 | H7: =F7-G7 -> 1739998 | I7: =G7/F7 -> 0.010781921
A8: Outlook Business | B8: 2020 | C8: 7 | D8: Jul-20 | E8: 7 | F8: 1289236 | G8: 15984 | H8: =F8-G8 -> 1273252 | I8: =G8/F8 -> 0.01239804
A9: Outlook Business | B9: 2020 | C9: 8 | D9: Aug-20 | E9: 8 | F9: 989236 | G9: 3256 | H9: =F9-G9 -> 985980 | I9: =G9/F9 -> 0.0032914289
A10: Outlook Business | B10: 2020 | C10: 9 | D10: Sep-20 | E10: 9 | F10: 653896 | G10: 11202 | H10: =F10-G10 -> 642694 | I10: =G10/F10 -> 0.017131165
A11: Outlook Business | B11: 2020 | C11: 10 | D11: Oct-20 | E11: 10 | F11: 474700 | G11: 12358 | H11: =F11-G11 -> 462342 | I11: =G11/F11 -> 0.026033284
A12: Outlook Business | B12: 2020 | C12: 11 | D12: Nov-20 | E12: 11 | F12: 396200 | G12: 8563 | H12: =F12-G12 -> 387637 | I12: =G12/F12 -> 0.021612822
A13: Outlook Business | B13: 2020 | C13: 12 | D13: Dec-20 | E13: 12 | F13: 823963 | G13: 5412 | H13: =F13-G13 -> 818551 | I13: =G13/F13 -> 0.0065682561
... A181: Outlook Traveller | B181: 2022 | C181: 12 | D181: Dec-22 | E181: 36 | F181: 286258 | G181: 2505 | H181: =F181-G181 -> 283753 | I181: =G181/F181 -> 0.0087508471
A182: Outlook Group (All Titles) | B182: 2020 | C182: 1 | D182: Jan-20 | E182: 1 | F182: =SUMIFS($F$2:$F181,$E$2:$E181,E182) -> 2195848 | G182: =SUMIFS($G$2:$G181,$E$2:$E181,E182) -> 20171 | H182: =F182-G182 -> 2175677 | I182: =G182/F182 -> 0.0091859728
A183: Outlook Group (All Titles) | B183: 2020 | C183: 2 | D183: Feb-20 | E183: 2 | F183: =SUMIFS($F$2:$F181,$E$2:$E181,E183) -> 2207257 | G183: =SUMIFS($G$2:$G181,$E$2:$E181,E183) -> 10081 | H183: =F183-G183 -> 2197176 | I183: =G183/F183 -> 0.0045672072
A184: Outlook Group (All Titles) | B184: 2020 | C184: 3 | D184: Mar-20 | E184: 3 | F184: =SUMIFS($F$2:$F181,$E$2:$E181,E184) -> 3083281 | G184: =SUMIFS($G$2:$G181,$E$2:$E181,E184) -> 18189 | H184: =F184-G184 -> 3065092 | I184: =G184/F184 -> 0.0058992353
A185: Outlook Group (All Titles) | B185: 2020 | C185: 4 | D185: Apr-20 | E185: 4 | F185: =SUMIFS($F$2:$F181,$E$2:$E181,E185) -> 2496851 | G185: =SUMIFS($G$2:$G181,$E$2:$E181,E185) -> 21643 | H185: =F185-G185 -> 2475208 | I185: =G185/F185 -> 0.0086681184
A186: Outlook Group (All Titles) | B186: 2020 | C186: 5 | D186: May-20 | E186: 5 | F186: =SUMIFS($F$2:$F181,$E$2:$E181,E186) -> 3340891 | G186: =SUMIFS($G$2:$G181,$E$2:$E181,E186) -> 18123 | H186: =F186-G186 -> 3322768 | I186: =G186/F186 -> 0.0054246008
A187: Outlook Group (All Titles) | B187: 2020 | C187: 6 | D187: Jun-20 | E187: 6 | F187: =SUMIFS($F$2:$F181,$E$2:$E181,E187) -> 3937405 | G187: =SUMIFS($G$2:$G181,$E$2:$E181,E187) -> 30380 | H187: =F187-G187 -> 3907025 | I187: =G187/F187 -> 0.0077157417
A188: Outlook Group (All Titles) | B188: 2020 | C188: 7 | D188: Jul-20 | E188: 7 | F188: =SUMIFS($F$2:$F181,$E$2:$E181,E188) -> 3236264 | G188: =SUMIFS($G$2:$G181,$E$2:$E181,E188) -> 27920 | H188: =F188-G188 -> 3208344 | I188: =G188/F188 -> 0.0086272319
A189: Outlook Group (All Titles) | B189: 2020 | C189: 8 | D189: Aug-20 | E189: 8 | F189: =SUMIFS($F$2:$F181,$E$2:$E181,E189) -> 2978169 | G189: =SUMIFS($G$2:$G181,$E$2:$E181,E189) -> 9510 | H189: =F189-G189 -> 2968659 | I189: =G189/F189 -> 0.0031932372
A190: Outlook Group (All Titles) | B190: 2020 | C190: 9 | D190: Sep-20 | E190: 9 | F190: =SUMIFS($F$2:$F181,$E$2:$E181,E190) -> 2944899 | G190: =SUMIFS($G$2:$G181,$E$2:$E181,E190) -> 22496 | H190: =F190-G190 -> 2922403 | I190: =G190/F190 -> 0.0076389717
A191: Outlook Group (All Titles) | B191: 2020 | C191: 10 | D191: Oct-20 | E191: 10 | F191: =SUMIFS($F$2:$F181,$E$2:$E181,E191) -> 2574803 | G191: =SUMIFS($G$2:$G181,$E$2:$E181,E191) -> 26136 | H191: =F191-G191 -> 2548667 | I191: =G191/F191 -> 0.010150679
A192: Outlook Group (All Titles) | B192: 2020 | C192: 11 | D192: Nov-20 | E192: 11 | F192: =SUMIFS($F$2:$F181,$E$2:$E181,E192) -> 2560547 | G192: =SUMIFS($G$2:$G181,$E$2:$E181,E192) -> 16599 | H192: =F192-G192 -> 2543948 | I192: =G192/F192 -> 0.0064825992
A193: Outlook Group (All Titles) | B193: 2020 | C193: 12 | D193: Dec-20 | E193: 12 | F193: =SUMIFS($F$2:$F181,$E$2:$E181,E193) -> 3445867 | G193: =SUMIFS($G$2:$G181,$E$2:$E181,E193) -> 15482 | H193: =F193-G193 -> 3430385 | I193: =G193/F193 -> 0.0044929186
A194: Outlook Group (All Titles) | B194: 2021 | C194: 1 | D194: Jan-21 | E194: 13 | F194: =SUMIFS($F$2:$F181,$E$2:$E181,E194) -> 1583647 | G194: =SUMIFS($G$2:$G181,$E$2:$E181,E194) -> 11325 | H194: =F194-G194 -> 1572322 | I194: =G194/F194 -> 0.0071512149
A195: Outlook Group (All Titles) | B195: 2021 | C195: 2 | D195: Feb-21 | E195: 14 | F195: =SUMIFS($F$2:$F181,$E$2:$E181,E195) -> 1604770 | G195: =SUMIFS($G$2:$G181,$E$2:$E181,E195) -> 14346 | H195: =F195-G195 -> 1590424 | I195: =G195/F195 -> 0.0089395988
A196: Outlook Group (All Titles) | B196: 2021 | C196: 3 | D196: Mar-21 | E196: 15 | F196: =SUMIFS($F$2:$F181,$E$2:$E181,E196) -> 1842473 | G196: =SUMIFS($G$2:$G181,$E$2:$E181,E196) -> 22753 | H196: =F196-G196 -> 1819720 | I196: =G196/F196 -> 0.012349163
A197: Outlook Group (All Titles) | B197: 2021 | C197: 4 | D197: Apr-21 | E197: 16 | F197: =SUMIFS($F$2:$F181,$E$2:$E181,E197) -> 2803601 | G197: =SUMIFS($G$2:$G181,$E$2:$E181,E197) -> 23990 | H197: =F197-G197 -> 2779611 | I197: =G197/F197 -> 0.0085568524
A198: Outlook Group (All Titles) | B198: 2021 | C198: 5 | D198: May-21 | E198: 17 | F198: =SUMIFS($F$2:$F181,$E$2:$E181,E198) -> 2215511 | G198: =SUMIFS($G$2:$G181,$E$2:$E181,E198) -> 28754 | H198: =F198-G198 -> 2186757 | I198: =G198/F198 -> 0.012978496
A199: Outlook Group (All Titles) | B199: 2021 | C199: 6 | D199: Jun-21 | E199: 18 | F199: =SUMIFS($F$2:$F181,$E$2:$E181,E199) -> 2225063 | G199: =SUMIFS($G$2:$G181,$E$2:$E181,E199) -> 13341 | H199: =F199-G199 -> 2211722 | I199: =G199/F199 -> 0.0059957853
A200: Outlook Group (All Titles) | B200: 2021 | C200: 7 | D200: Jul-21 | E200: 19 | F200: =SUMIFS($F$2:$F181,$E$2:$E181,E200) -> 2681359 | G200: =SUMIFS($G$2:$G181,$E$2:$E181,E200) -> 16131 | H200: =F200-G200 -> 2665228 | I200: =G200/F200 -> 0.0060159792
A201: Outlook Group (All Titles) | B201: 2021 | C201: 8 | D201: Aug-21 | E201: 20 | F201: =SUMIFS($F$2:$F181,$E$2:$E181,E201) -> 2415011 | G201: =SUMIFS($G$2:$G181,$E$2:$E181,E201) -> 11080 | H201: =F201-G201 -> 2403931 | I201: =G201/F201 -> 0.0045879708
A202: Outlook Group (All Titles) | B202: 2021 | C202: 9 | D202: Sep-21 | E202: 21 | F202: =SUMIFS($F$2:$F181,$E$2:$E181,E202) -> 2699748 | G202: =SUMIFS($G$2:$G181,$E$2:$E181,E202) -> 22721 | H202: =F202-G202 -> 2677027 | I202: =G202/F202 -> 0.0084159707
A203: Outlook Group (All Titles) | B203: 2021 | C203: 10 | D203: Oct-21 | E203: 22 | F203: =SUMIFS($F$2:$F181,$E$2:$E181,E203) -> 2116643 | G203: =SUMIFS($G$2:$G181,$E$2:$E181,E203) -> 17821 | H203: =F203-G203 -> 2098822 | I203: =G203/F203 -> 0.0084194642
A204: Outlook Group (All Titles) | B204: 2021 | C204: 11 | D204: Nov-21 | E204: 23 | F204: =SUMIFS($F$2:$F181,$E$2:$E181,E204) -> 2436477 | G204: =SUMIFS($G$2:$G181,$E$2:$E181,E204) -> 16560 | H204: =F204-G204 -> 2419917 | I204: =G204/F204 -> 0.0067966987
A205: Outlook Group (All Titles) | B205: 2021 | C205: 12 | D205: Dec-21 | E205: 24 | F205: =SUMIFS($F$2:$F181,$E$2:$E181,E205) -> 2234435 | G205: =SUMIFS($G$2:$G181,$E$2:$E181,E205) -> 15717 | H205: =F205-G205 -> 2218718 | I205: =G205/F205 -> 0.0070339929
A206: Outlook Group (All Titles) | B206: 2022 | C206: 1 | D206: Jan-22 | E206: 25 | F206: =SUMIFS($F$2:$F181,$E$2:$E181,E206) -> 2334961 | G206: =SUMIFS($G$2:$G181,$E$2:$E181,E206) -> 13998 | H206: =F206-G206 -> 2320963 | I206: =G206/F206 -> 0.0059949609
A207: Outlook Group (All Titles) | B207: 2022 | C207: 2 | D207: Feb-22 | E207: 26 | F207: =SUMIFS($F$2:$F181,$E$2:$E181,E207) -> 2389843 | G207: =SUMIFS($G$2:$G181,$E$2:$E181,E207) -> 11439 | H207: =F207-G207 -> 2378404 | I207: =G207/F207 -> 0.0047865069
...

Sheet Outlook Business Analysis
B2: Outlook Business — Forecast Analysis
B3: How is Outlook Business trending month to month, and what should Q1 2023 planning assume?
I4: Trendline stats
B5: Month | C5: MonthIndex | D5: Actual Sales | E5: WMA (3-mo) | F5: Linear Trend | I5: Slope (per month) | J5: =SLOPE(D6:D41,C6:C41) -> 2379.2243
B6: ='Monthly Data'!D2 -> Jan-20 | C6: ='Monthly Data'!E2 -> 1 | D6: ='Monthly Data'!F2 -> 732234 | F6: =$J$6+$J$5*C6 -> 908573.6 | I6: Intercept | J6: =INTERCEPT(D6:D41,C6:C41) -> 906194.38
B7: ='Monthly Data'!D3 -> Feb-20 | C7: ='Monthly Data'!E3 -> 2 | D7: ='Monthly Data'!F3 -> 639999 | F7: =$J$6+$J$5*C7 -> 910952.83 | I7: R-squared | J7: =RSQ(D6:D41,C6:C41) -> 0.0028801432
B8: ='Monthly Data'!D4 -> Mar-20 | C8: ='Monthly Data'!E4 -> 3 | D8: ='Monthly Data'!F4 -> 1289369 | E8: =(1*D6+2*D7+3*D8)/6 -> 980056.5 | F8: =$J$6+$J$5*C8 -> 913332.05 | I8: Mean churn rate | J8: =AVERAGE('Monthly Data'!I2:I37) -> 0.010729632
B9: ='Monthly Data'!D5 -> Apr-20 | C9: ='Monthly Data'!E5 -> 4 | D9: ='Monthly Data'!F5 -> 789213 | E9: =(1*D7+2*D8+3*D9)/6 -> 931062.67 | F9: =$J$6+$J$5*C9 -> 915711.28
B10: ='Monthly Data'!D6 -> May-20 | C10: ='Monthly Data'!E6 -> 5 | D10: ='Monthly Data'!F6 -> 1558639 | E10: =(1*D8+2*D9+3*D10)/6 -> 1257285.3 | F10: =$J$6+$J$5*C10 -> 918090.5
B11: ='Monthly Data'!D7 -> Jun-20 | C11: ='Monthly Data'!E7 -> 6 | D11: ='Monthly Data'!F7 -> 1758963 | E11: =(1*D9+2*D10+3*D11)/6 -> 1530563.3 | F11: =$J$6+$J$5*C11 -> 920469.72
B12: ='Monthly Data'!D8 -> Jul-20 | C12: ='Monthly Data'!E8 -> 7 | D12: ='Monthly Data'!F8 -> 1289236 | E12: =(1*D10+2*D11+3*D12)/6 -> 1490712.2 | F12: =$J$6+$J$5*C12 -> 922848.95
B13: ='Monthly Data'!D9 -> Aug-20 | C13: ='Monthly Data'!E9 -> 8 | D13: ='Monthly Data'!F9 -> 989236 | E13: =(1*D11+2*D12+3*D13)/6 -> 1217523.8 | F13: =$J$6+$J$5*C13 -> 925228.17
B14: ='Monthly Data'!D10 -> Sep-20 | C14: ='Monthly Data'!E10 -> 9 | D14: ='Monthly Data'!F10 -> 653896 | E14: =(1*D12+2*D13+3*D14)/6 -> 871566 | F14: =$J$6+$J$5*C14 -> 927607.4
B15: ='Monthly Data'!D11 -> Oct-20 | C15: ='Monthly Data'!E11 -> 10 | D15: ='Monthly Data'!F11 -> 474700 | E15: =(1*D13+2*D14+3*D15)/6 -> 620188 | F15: =$J$6+$J$5*C15 -> 929986.62
B16: ='Monthly Data'!D12 -> Nov-20 | C16: ='Monthly Data'!E12 -> 11 | D16: ='Monthly Data'!F12 -> 396200 | E16: =(1*D14+2*D15+3*D16)/6 -> 465316 | F16: =$J$6+$J$5*C16 -> 932365.85
B17: ='Monthly Data'!D13 -> Dec-20 | C17: ='Monthly Data'!E13 -> 12 | D17: ='Monthly Data'!F13 -> 823963 | E17: =(1*D15+2*D16+3*D17)/6 -> 623164.83 | F17: =$J$6+$J$5*C17 -> 934745.07
B18: ='Monthly Data'!D14 -> Jan-21 | C18: ='Monthly Data'!E14 -> 13 | D18: ='Monthly Data'!F14 -> 526563 | E18: =(1*D16+2*D17+3*D18)/6 -> 603969.17 | F18: =$J$6+$J$5*C18 -> 937124.29
B19: ='Monthly Data'!D15 -> Feb-21 | C19: ='Monthly Data'!E15 -> 14 | D19: ='Monthly Data'!F15 -> 485636 | E19: =(1*D17+2*D18+3*D19)/6 -> 555666.17 | F19: =$J$6+$J$5*C19 -> 939503.52
B20: ='Monthly Data'!D16 -> Mar-21 | C20: ='Monthly Data'!E16 -> 15 | D20: ='Monthly Data'!F16 -> 589187 | E20: =(1*D18+2*D19+3*D20)/6 -> 544232.67 | F20: =$J$6+$J$5*C20 -> 941882.74
... B41: ='Monthly Data'!D37 -> Dec-22 | C41: ='Monthly Data'!E37 -> 36 | D41: ='Monthly Data'!F37 -> 978523 | E41: =(1*D39+2*D40+3*D41)/6 -> 767388.83 | F41: =$J$6+$J$5*C41 -> 991846.45
B42: Jan-23 | C42: 37 | E42: =(1*D39+2*D40+3*D41)/6 -> 767388.83 | F42: =$J$6+$J$5*C42 -> 994225.68
B43: Feb-23 | C43: 38 | E43: =(1*D40+2*D41+3*E42)/6 -> 807385.42 | F43: =$J$6+$J$5*C43 -> 996604.9
B44: Mar-23 | C44: 39 | E44: =(1*D41+2*E42+3*E43)/6 -> 822576.15 | F44: =$J$6+$J$5*C44 -> 998984.13
B47: Preprocessing notes
B48: Monthly data used as reported (already monthly cadence).
B51: Interpretation & recommendation
B52: • 2020->2021 fell 14.3%, then 2021->2022 rose 33.5%, netting +14.4% over the 3-year window.
B53: • Linear trend R² is very low (~0.00) — essentially no reliable straight-line monthly trend; treat the trendline forecast as a weak baseline only, and lean on the WMA for near-term planning.

Sheet Outlook Hindi Analysis
B2: Outlook Hindi — Forecast Analysis
B3: How is Outlook Hindi trending, given its fortnightly (26 issue/year) publishing cycle?
I4: Trendline stats
B5: Month | C5: MonthIndex | D5: Actual Sales | E5: WMA (3-mo) | F5: Linear Trend | I5: Slope (per month) | J5: =SLOPE(D6:D41,C6:C41) -> 4071.6849
B6: ='Monthly Data'!D38 -> Jan-20 | C6: ='Monthly Data'!E38 -> 1 | D6: ='Monthly Data'!F38 -> 162899 | F6: =$J$6+$J$5*C6 -> 204619.35 | I6: Intercept | J6: =INTERCEPT(D6:D41,C6:C41) -> 200547.66
B7: ='Monthly Data'!D39 -> Feb-20 | C7: ='Monthly Data'!E39 -> 2 | D7: ='Monthly Data'!F39 -> 176099 | F7: =$J$6+$J$5*C7 -> 208691.03 | I7: R-squared | J7: =RSQ(D6:D41,C6:C41) -> 0.24873153
B8: ='Monthly Data'!D40 -> Mar-20 | C8: ='Monthly Data'!E40 -> 3 | D8: ='Monthly Data'!F40 -> 186764 | E8: =(1*D6+2*D7+3*D8)/6 -> 179231.5 | F8: =$J$6+$J$5*C8 -> 212762.72 | I8: Mean churn rate | J8: =AVERAGE('Monthly Data'!I38:I73) -> 0.0066107512
B9: ='Monthly Data'!D41 -> Apr-20 | C9: ='Monthly Data'!E41 -> 4 | D9: ='Monthly Data'!F41 -> 199499 | E9: =(1*D7+2*D8+3*D9)/6 -> 191354 | F9: =$J$6+$J$5*C9 -> 216834.4
B10: ='Monthly Data'!D42 -> May-20 | C10: ='Monthly Data'!E42 -> 5 | D10: ='Monthly Data'!F42 -> 208591 | E10: =(1*D8+2*D9+3*D10)/6 -> 201922.5 | F10: =$J$6+$J$5*C10 -> 220906.09
B11: ='Monthly Data'!D43 -> Jun-20 | C11: ='Monthly Data'!E43 -> 6 | D11: ='Monthly Data'!F43 -> 340737 | E11: =(1*D9+2*D10+3*D11)/6 -> 273148.67 | F11: =$J$6+$J$5*C11 -> 224977.77
B12: ='Monthly Data'!D44 -> Jul-20 | C12: ='Monthly Data'!E44 -> 7 | D12: ='Monthly Data'!F44 -> 238052 | E12: =(1*D10+2*D11+3*D12)/6 -> 267370.17 | F12: =$J$6+$J$5*C12 -> 229049.46
B13: ='Monthly Data'!D45 -> Aug-20 | C13: ='Monthly Data'!E45 -> 8 | D13: ='Monthly Data'!F45 -> 248527 | E13: =(1*D11+2*D12+3*D13)/6 -> 260403.67 | F13: =$J$6+$J$5*C13 -> 233121.14
B14: ='Monthly Data'!D46 -> Sep-20 | C14: ='Monthly Data'!E46 -> 9 | D14: ='Monthly Data'!F46 -> 260195 | E14: =(1*D12+2*D13+3*D14)/6 -> 252615.17 | F14: =$J$6+$J$5*C14 -> 237192.83
B15: ='Monthly Data'!D47 -> Oct-20 | C15: ='Monthly Data'!E47 -> 10 | D15: ='Monthly Data'!F47 -> 269879 | E15: =(1*D13+2*D14+3*D15)/6 -> 263092.33 | F15: =$J$6+$J$5*C15 -> 241264.51
B16: ='Monthly Data'!D48 -> Nov-20 | C16: ='Monthly Data'!E48 -> 11 | D16: ='Monthly Data'!F48 -> 282528 | E16: =(1*D14+2*D15+3*D16)/6 -> 274589.5 | F16: =$J$6+$J$5*C16 -> 245336.2
B17: ='Monthly Data'!D49 -> Dec-20 | C17: ='Monthly Data'!E49 -> 12 | D17: ='Monthly Data'!F49 -> 440769 | E17: =(1*D15+2*D16+3*D17)/6 -> 359540.33 | F17: =$J$6+$J$5*C17 -> 249407.88
B18: ='Monthly Data'!D50 -> Jan-21 | C18: ='Monthly Data'!E50 -> 13 | D18: ='Monthly Data'!F50 -> 187762 | E18: =(1*D16+2*D17+3*D18)/6 -> 287892 | F18: =$J$6+$J$5*C18 -> 253479.57
B19: ='Monthly Data'!D51 -> Feb-21 | C19: ='Monthly Data'!E51 -> 14 | D19: ='Monthly Data'!F51 -> 196055 | E19: =(1*D17+2*D18+3*D19)/6 -> 234076.33 | F19: =$J$6+$J$5*C19 -> 257551.25
B20: ='Monthly Data'!D52 -> Mar-21 | C20: ='Monthly Data'!E52 -> 15 | D20: ='Monthly Data'!F52 -> 209881 | E20: =(1*D18+2*D19+3*D20)/6 -> 201585.83 | F20: =$J$6+$J$5*C20 -> 261622.94
... B41: ='Monthly Data'!D73 -> Dec-22 | C41: ='Monthly Data'!E73 -> 36 | D41: ='Monthly Data'!F73 -> 545134 | E41: =(1*D39+2*D40+3*D41)/6 -> 444645.17 | F41: =$J$6+$J$5*C41 -> 347128.32
B42: Jan-23 | C42: 37 | E42: =(1*D39+2*D40+3*D41)/6 -> 444645.17 | F42: =$J$6+$J$5*C42 -> 351200
B43: Feb-23 | C43: 38 | E43: =(1*D40+2*D41+3*E42)/6 -> 462183.58 | F43: =$J$6+$J$5*C43 -> 355271.69
B44: Mar-23 | C44: 39 | E44: =(1*D41+2*E42+3*E43)/6 -> 470162.51 | F44: =$J$6+$J$5*C44 -> 359343.37
B47: Preprocessing notes
B48: 26 fortnightly issues/year mapped to calendar months (issue i -> month = CEILING(i*12/26)) and summed.
B51: Interpretation & recommendation
B52: • Steadiest grower of all 5 titles: +7.8% (20-21), +12.9% (21-22), +21.7% total — no 2021 dip.
B53: • Linear R²=0.25, the second-highest of any title — its growth is closer to a genuine steady climb than the others.

Sheet Outlook India Analysis
B2: Outlook India — Forecast Analysis
B3: How is Outlook India trending, given its weekly (52 issue/year) publishing cycle, and what drove its sharp 2021 trough?
I4: Trendline stats
B5: Month | C5: MonthIndex | D5: Actual Sales | E5: WMA (3-mo) | F5: Linear Trend | I5: Slope (per month) | J5: =SLOPE(D6:D41,C6:C41) -> 20979.429
B6: ='Monthly Data'!D74 -> Jan-20 | C6: ='Monthly Data'!E74 -> 1 | D6: ='Monthly Data'!F74 -> 528166 | F6: =$J$6+$J$5*C6 -> 506824.56 | I6: Intercept | J6: =INTERCEPT(D6:D41,C6:C41) -> 485845.13
B7: ='Monthly Data'!D75 -> Feb-20 | C7: ='Monthly Data'!E75 -> 2 | D7: ='Monthly Data'!F75 -> 612054 | F7: =$J$6+$J$5*C7 -> 527803.98 | I7: R-squared | J7: =RSQ(D6:D41,C6:C41) -> 0.2693034
B8: ='Monthly Data'!D76 -> Mar-20 | C8: ='Monthly Data'!E76 -> 3 | D8: ='Monthly Data'!F76 -> 814016 | E8: =(1*D6+2*D7+3*D8)/6 -> 699053.67 | F8: =$J$6+$J$5*C8 -> 548783.41 | I8: Mean churn rate | J8: =AVERAGE('Monthly Data'!I74:I109) -> 0.007162396
B9: ='Monthly Data'!D77 -> Apr-20 | C9: ='Monthly Data'!E77 -> 4 | D9: ='Monthly Data'!F77 -> 705349 | E9: =(1*D7+2*D8+3*D9)/6 -> 726022.17 | F9: =$J$6+$J$5*C9 -> 569762.84
B10: ='Monthly Data'!D78 -> May-20 | C10: ='Monthly Data'!E78 -> 5 | D10: ='Monthly Data'!F78 -> 763211 | E10: =(1*D8+2*D9+3*D10)/6 -> 752391.17 | F10: =$J$6+$J$5*C10 -> 590742.27
B11: ='Monthly Data'!D79 -> Jun-20 | C11: ='Monthly Data'!E79 -> 6 | D11: ='Monthly Data'!F79 -> 1024206 | E11: =(1*D9+2*D10+3*D11)/6 -> 884064.83 | F11: =$J$6+$J$5*C11 -> 611721.7
B12: ='Monthly Data'!D80 -> Jul-20 | C12: ='Monthly Data'!E80 -> 7 | D12: ='Monthly Data'!F80 -> 885858 | E12: =(1*D10+2*D11+3*D12)/6 -> 911532.83 | F12: =$J$6+$J$5*C12 -> 632701.13
B13: ='Monthly Data'!D81 -> Aug-20 | C13: ='Monthly Data'!E81 -> 8 | D13: ='Monthly Data'!F81 -> 911106 | E13: =(1*D11+2*D12+3*D13)/6 -> 921540 | F13: =$J$6+$J$5*C13 -> 653680.56
B14: ='Monthly Data'!D82 -> Sep-20 | C14: ='Monthly Data'!E82 -> 9 | D14: ='Monthly Data'!F82 -> 1188976 | E14: =(1*D12+2*D13+3*D14)/6 -> 1045833 | F14: =$J$6+$J$5*C14 -> 674659.98
B15: ='Monthly Data'!D83 -> Oct-20 | C15: ='Monthly Data'!E83 -> 10 | D15: ='Monthly Data'!F83 -> 985516 | E15: =(1*D13+2*D14+3*D15)/6 -> 1040934.3 | F15: =$J$6+$J$5*C15 -> 695639.41
B16: ='Monthly Data'!D84 -> Nov-20 | C16: ='Monthly Data'!E84 -> 11 | D16: ='Monthly Data'!F84 -> 1025684 | E16: =(1*D14+2*D15+3*D16)/6 -> 1039510 | F16: =$J$6+$J$5*C16 -> 716618.84
B17: ='Monthly Data'!D85 -> Dec-20 | C17: ='Monthly Data'!E85 -> 12 | D17: ='Monthly Data'!F85 -> 1319690 | E17: =(1*D15+2*D16+3*D17)/6 -> 1165992.3 | F17: =$J$6+$J$5*C17 -> 737598.27
B18: ='Monthly Data'!D86 -> Jan-21 | C18: ='Monthly Data'!E86 -> 13 | D18: ='Monthly Data'!F86 -> 219161 | E18: =(1*D16+2*D17+3*D18)/6 -> 720424.5 | F18: =$J$6+$J$5*C18 -> 758577.7
B19: ='Monthly Data'!D87 -> Feb-21 | C19: ='Monthly Data'!E87 -> 14 | D19: ='Monthly Data'!F87 -> 261639 | E19: =(1*D17+2*D18+3*D19)/6 -> 423821.5 | F19: =$J$6+$J$5*C19 -> 779557.13
B20: ='Monthly Data'!D88 -> Mar-21 | C20: ='Monthly Data'!E88 -> 15 | D20: ='Monthly Data'!F88 -> 375358 | E20: =(1*D18+2*D19+3*D20)/6 -> 311418.83 | F20: =$J$6+$J$5*C20 -> 800536.56
... B41: ='Monthly Data'!D109 -> Dec-22 | C41: ='Monthly Data'!E109 -> 36 | D41: ='Monthly Data'!F109 -> 1855391 | E41: =(1*D39+2*D40+3*D41)/6 -> 1664768.7 | F41: =$J$6+$J$5*C41 -> 1241104.6
B42: Jan-23 | C42: 37 | E42: =(1*D39+2*D40+3*D41)/6 -> 1664768.7 | F42: =$J$6+$J$5*C42 -> 1262084
B43: Feb-23 | C43: 38 | E43: =(1*D40+2*D41+3*E42)/6 -> 1698996.8 | F43: =$J$6+$J$5*C43 -> 1283063.4
B44: Mar-23 | C44: 39 | E44: =(1*D41+2*E42+3*E43)/6 -> 1713653.1 | F44: =$J$6+$J$5*C44 -> 1304042.8
B47: Preprocessing notes
B48: 52 weekly issues/year mapped to calendar months (issue i -> month = CEILING(i*12/52)) and summed.
B51: Interpretation & recommendation
B52: • Sharpest swing of all titles: -50.5% (20-21) then +188.1% (21-22), netting +42.8% — by far the strongest 3-year gain.
B53: • Polynomial (U-shaped) fit explains far more than the linear one (see Word report, R² 0.60 vs 0.27) — confirms a real trough-then-rebound shape, not just noise; worth a standalone case study into what drove the 2022 rebound.

Sheet Outlook Money Analysis
B2: Outlook Money — Forecast Analysis
B3: How is Outlook Money trending month to month, and what should Q1 2023 planning assume?
I4: Trendline stats
B5: Month | C5: MonthIndex | D5: Actual Sales | E5: WMA (3-mo) | F5: Linear Trend | I5: Slope (per month) | J5: =SLOPE(D6:D41,C6:C41) -> 1607.4866
B6: ='Monthly Data'!D110 -> Jan-20 | C6: ='Monthly Data'!E110 -> 1 | D6: ='Monthly Data'!F110 -> 541327 | F6: =$J$6+$J$5*C6 -> 521655.85 | I6: Intercept | J6: =INTERCEPT(D6:D41,C6:C41) -> 520048.36
B7: ='Monthly Data'!D111 -> Feb-20 | C7: ='Monthly Data'!E111 -> 2 | D7: ='Monthly Data'!F111 -> 543521 | F7: =$J$6+$J$5*C7 -> 523263.33 | I7: R-squared | J7: =RSQ(D6:D41,C6:C41) -> 0.13005664
B8: ='Monthly Data'!D112 -> Mar-20 | C8: ='Monthly Data'!E112 -> 3 | D8: ='Monthly Data'!F112 -> 553236 | E8: =(1*D6+2*D7+3*D8)/6 -> 548012.83 | F8: =$J$6+$J$5*C8 -> 524870.82 | I8: Mean churn rate | J8: =AVERAGE('Monthly Data'!I110:I145) -> 0.0044519576
B9: ='Monthly Data'!D113 -> Apr-20 | C9: ='Monthly Data'!E113 -> 4 | D9: ='Monthly Data'!F113 -> 559221 | E9: =(1*D7+2*D8+3*D9)/6 -> 554609.33 | F9: =$J$6+$J$5*C9 -> 526478.31
B10: ='Monthly Data'!D114 -> May-20 | C10: ='Monthly Data'!E114 -> 5 | D10: ='Monthly Data'!F114 -> 562852 | E10: =(1*D8+2*D9+3*D10)/6 -> 560039 | F10: =$J$6+$J$5*C10 -> 528085.79
B11: ='Monthly Data'!D115 -> Jun-20 | C11: ='Monthly Data'!E115 -> 6 | D11: ='Monthly Data'!F115 -> 564236 | E11: =(1*D9+2*D10+3*D11)/6 -> 562938.83 | F11: =$J$6+$J$5*C11 -> 529693.28
B12: ='Monthly Data'!D116 -> Jul-20 | C12: ='Monthly Data'!E116 -> 7 | D12: ='Monthly Data'!F116 -> 568222 | E12: =(1*D10+2*D11+3*D12)/6 -> 565998.33 | F12: =$J$6+$J$5*C12 -> 531300.77
B13: ='Monthly Data'!D117 -> Aug-20 | C13: ='Monthly Data'!E117 -> 8 | D13: ='Monthly Data'!F117 -> 571200 | E13: =(1*D11+2*D12+3*D13)/6 -> 569046.67 | F13: =$J$6+$J$5*C13 -> 532908.25
B14: ='Monthly Data'!D118 -> Sep-20 | C14: ='Monthly Data'!E118 -> 9 | D14: ='Monthly Data'!F118 -> 573632 | E14: =(1*D12+2*D13+3*D14)/6 -> 571919.67 | F14: =$J$6+$J$5*C14 -> 534515.74
B15: ='Monthly Data'!D119 -> Oct-20 | C15: ='Monthly Data'!E119 -> 10 | D15: ='Monthly Data'!F119 -> 575121 | E15: =(1*D13+2*D14+3*D15)/6 -> 573971.17 | F15: =$J$6+$J$5*C15 -> 536123.22
B16: ='Monthly Data'!D120 -> Nov-20 | C16: ='Monthly Data'!E120 -> 11 | D16: ='Monthly Data'!F120 -> 580537 | E16: =(1*D14+2*D15+3*D16)/6 -> 577580.83 | F16: =$J$6+$J$5*C16 -> 537730.71
B17: ='Monthly Data'!D121 -> Dec-20 | C17: ='Monthly Data'!E121 -> 12 | D17: ='Monthly Data'!F121 -> 582923 | E17: =(1*D15+2*D16+3*D17)/6 -> 580827.33 | F17: =$J$6+$J$5*C17 -> 539338.2
B18: ='Monthly Data'!D122 -> Jan-21 | C18: ='Monthly Data'!E122 -> 13 | D18: ='Monthly Data'!F122 -> 460896 | E18: =(1*D16+2*D17+3*D18)/6 -> 521511.83 | F18: =$J$6+$J$5*C18 -> 540945.68
B19: ='Monthly Data'!D123 -> Feb-21 | C19: ='Monthly Data'!E123 -> 14 | D19: ='Monthly Data'!F123 -> 465852 | E19: =(1*D17+2*D18+3*D19)/6 -> 483711.83 | F19: =$J$6+$J$5*C19 -> 542553.17
B20: ='Monthly Data'!D124 -> Mar-21 | C20: ='Monthly Data'!E124 -> 15 | D20: ='Monthly Data'!F124 -> 469521 | E20: =(1*D18+2*D19+3*D20)/6 -> 466860.5 | F20: =$J$6+$J$5*C20 -> 544160.66
... B41: ='Monthly Data'!D145 -> Dec-22 | C41: ='Monthly Data'!E145 -> 36 | D41: ='Monthly Data'!F145 -> 621200 | E41: =(1*D39+2*D40+3*D41)/6 -> 617937.17 | F41: =$J$6+$J$5*C41 -> 577917.88
B42: Jan-23 | C42: 37 | E42: =(1*D39+2*D40+3*D41)/6 -> 617937.17 | F42: =$J$6+$J$5*C42 -> 579525.36
B43: Feb-23 | C43: 38 | E43: =(1*D40+2*D41+3*E42)/6 -> 618680.08 | F43: =$J$6+$J$5*C43 -> 581132.85
B44: Mar-23 | C44: 39 | E44: =(1*D41+2*E42+3*E43)/6 -> 618852.43 | F44: =$J$6+$J$5*C44 -> 582740.34
B47: Preprocessing notes
B48: Monthly data used as reported (already monthly cadence).
B51: Interpretation & recommendation
B52: • 2020->2021 fell 12.9%, 2021->2022 rose 20.6%, netting only +5.0% — weakest recovery of the 5 titles.
B53: • Polynomial fit (R²=0.56) is much stronger than linear (R²=0.13) — same dip/recover shape as its peers, just a shallower rebound; worth monitoring alongside Traveller as the two laggards.

Sheet Outlook Traveller Analysis
B2: Outlook Traveller — Forecast Analysis
B3: How is Outlook Traveller trending month to month, and what should Q1 2023 planning assume?
I4: Trendline stats
B5: Month | C5: MonthIndex | D5: Actual Sales | E5: WMA (3-mo) | F5: Linear Trend | I5: Slope (per month) | J5: =SLOPE(D6:D41,C6:C41) -> 548.48713
B6: ='Monthly Data'!D146 -> Jan-20 | C6: ='Monthly Data'!E146 -> 1 | D6: ='Monthly Data'!F146 -> 231222 | F6: =$J$6+$J$5*C6 -> 232201.56 | I6: Intercept | J6: =INTERCEPT(D6:D41,C6:C41) -> 231653.07
B7: ='Monthly Data'!D147 -> Feb-20 | C7: ='Monthly Data'!E147 -> 2 | D7: ='Monthly Data'!F147 -> 235584 | F7: =$J$6+$J$5*C7 -> 232750.05 | I7: R-squared | J7: =RSQ(D6:D41,C6:C41) -> 0.052142173
B8: ='Monthly Data'!D148 -> Mar-20 | C8: ='Monthly Data'!E148 -> 3 | D8: ='Monthly Data'!F148 -> 239896 | E8: =(1*D6+2*D7+3*D8)/6 -> 237013 | F8: =$J$6+$J$5*C8 -> 233298.53 | I8: Mean churn rate | J8: =AVERAGE('Monthly Data'!I146:I181) -> 0.0040291
B9: ='Monthly Data'!D149 -> Apr-20 | C9: ='Monthly Data'!E149 -> 4 | D9: ='Monthly Data'!F149 -> 243569 | E9: =(1*D7+2*D8+3*D9)/6 -> 241013.83 | F9: =$J$6+$J$5*C9 -> 233847.02
B10: ='Monthly Data'!D150 -> May-20 | C10: ='Monthly Data'!E150 -> 5 | D10: ='Monthly Data'!F150 -> 247598 | E10: =(1*D8+2*D9+3*D10)/6 -> 244971.33 | F10: =$J$6+$J$5*C10 -> 234395.51
B11: ='Monthly Data'!D151 -> Jun-20 | C11: ='Monthly Data'!E151 -> 6 | D11: ='Monthly Data'!F151 -> 249263 | E11: =(1*D9+2*D10+3*D11)/6 -> 247759 | F11: =$J$6+$J$5*C11 -> 234943.99
B12: ='Monthly Data'!D152 -> Jul-20 | C12: ='Monthly Data'!E152 -> 7 | D12: ='Monthly Data'!F152 -> 254896 | E12: =(1*D10+2*D11+3*D12)/6 -> 251802 | F12: =$J$6+$J$5*C12 -> 235492.48
B13: ='Monthly Data'!D153 -> Aug-20 | C13: ='Monthly Data'!E153 -> 8 | D13: ='Monthly Data'!F153 -> 258100 | E13: =(1*D11+2*D12+3*D13)/6 -> 255559.17 | F13: =$J$6+$J$5*C13 -> 236040.97
B14: ='Monthly Data'!D154 -> Sep-20 | C14: ='Monthly Data'!E154 -> 9 | D14: ='Monthly Data'!F154 -> 268200 | E14: =(1*D12+2*D13+3*D14)/6 -> 262616 | F14: =$J$6+$J$5*C14 -> 236589.46
B15: ='Monthly Data'!D155 -> Oct-20 | C15: ='Monthly Data'!E155 -> 10 | D15: ='Monthly Data'!F155 -> 269587 | E15: =(1*D13+2*D14+3*D15)/6 -> 267210.17 | F15: =$J$6+$J$5*C15 -> 237137.94
B16: ='Monthly Data'!D156 -> Nov-20 | C16: ='Monthly Data'!E156 -> 11 | D16: ='Monthly Data'!F156 -> 275598 | E16: =(1*D14+2*D15+3*D16)/6 -> 272361.33 | F16: =$J$6+$J$5*C16 -> 237686.43
B17: ='Monthly Data'!D157 -> Dec-20 | C17: ='Monthly Data'!E157 -> 12 | D17: ='Monthly Data'!F157 -> 278522 | E17: =(1*D15+2*D16+3*D17)/6 -> 276058.17 | F17: =$J$6+$J$5*C17 -> 238234.92
B18: ='Monthly Data'!D158 -> Jan-21 | C18: ='Monthly Data'!E158 -> 13 | D18: ='Monthly Data'!F158 -> 189265 | E18: =(1*D16+2*D17+3*D18)/6 -> 233406.17 | F18: =$J$6+$J$5*C18 -> 238783.4
B19: ='Monthly Data'!D159 -> Feb-21 | C19: ='Monthly Data'!E159 -> 14 | D19: ='Monthly Data'!F159 -> 195588 | E19: =(1*D17+2*D18+3*D19)/6 -> 207302.67 | F19: =$J$6+$J$5*C19 -> 239331.89
B20: ='Monthly Data'!D160 -> Mar-21 | C20: ='Monthly Data'!E160 -> 15 | D20: ='Monthly Data'!F160 -> 198526 | E20: =(1*D18+2*D19+3*D20)/6 -> 196003.17 | F20: =$J$6+$J$5*C20 -> 239880.38
... B41: ='Monthly Data'!D181 -> Dec-22 | C41: ='Monthly Data'!E181 -> 36 | D41: ='Monthly Data'!F181 -> 286258 | E41: =(1*D39+2*D40+3*D41)/6 -> 282089.67 | F41: =$J$6+$J$5*C41 -> 251398.61
B42: Jan-23 | C42: 37 | E42: =(1*D39+2*D40+3*D41)/6 -> 282089.67 | F42: =$J$6+$J$5*C42 -> 251947.1
B43: Feb-23 | C43: 38 | E43: =(1*D40+2*D41+3*E42)/6 -> 283002.67 | F43: =$J$6+$J$5*C43 -> 252495.58
B44: Mar-23 | C44: 39 | E44: =(1*D41+2*E42+3*E43)/6 -> 283240.89 | F44: =$J$6+$J$5*C44 -> 253044.07
B47: Preprocessing notes
B48: Monthly data used as reported (already monthly cadence).
B51: Interpretation & recommendation
B52: • Effectively flat over 3 years: 2022 average is 0.2% below 2020, despite a +16.9% bounce from the 2021 trough.
B53: • The only title that has not fully recovered its 2020 level — plausible given travel-sector disruption ran longer than other categories; worth a travel-specific promotional push into Q1 2023.

Sheet Outlook Group Analysis
B2: Outlook Group (All Titles) — Forecast Analysis
B3: Summed across all 5 titles, what is The Outlook Group's overall growth trajectory, and what should the Q1 2023 forecast be?
I4: Trendline stats
B5: Month | C5: MonthIndex | D5: Actual Sales | E5: WMA (3-mo) | F5: Linear Trend | I5: Slope (per month) | J5: =SLOPE(D6:D41,C6:C41) -> 29586.312
B6: ='Monthly Data'!D182 -> Jan-20 | C6: ='Monthly Data'!E182 -> 1 | D6: ='Monthly Data'!F182 -> 2195848 | F6: =$J$6+$J$5*C6 -> 2373874.9 | I6: Intercept | J6: =INTERCEPT(D6:D41,C6:C41) -> 2344288.6
B7: ='Monthly Data'!D183 -> Feb-20 | C7: ='Monthly Data'!E183 -> 2 | D7: ='Monthly Data'!F183 -> 2207257 | F7: =$J$6+$J$5*C7 -> 2403461.2 | I7: R-squared | J7: =RSQ(D6:D41,C6:C41) -> 0.17099671
B8: ='Monthly Data'!D184 -> Mar-20 | C8: ='Monthly Data'!E184 -> 3 | D8: ='Monthly Data'!F184 -> 3083281 | E8: =(1*D6+2*D7+3*D8)/6 -> 2643367.5 | F8: =$J$6+$J$5*C8 -> 2433047.5 | I8: Mean churn rate | J8: =AVERAGE('Monthly Data'!I182:I217) -> 0.0068970944
B9: ='Monthly Data'!D185 -> Apr-20 | C9: ='Monthly Data'!E185 -> 4 | D9: ='Monthly Data'!F185 -> 2496851 | E9: =(1*D7+2*D8+3*D9)/6 -> 2644062 | F9: =$J$6+$J$5*C9 -> 2462633.8
B10: ='Monthly Data'!D186 -> May-20 | C10: ='Monthly Data'!E186 -> 5 | D10: ='Monthly Data'!F186 -> 3340891 | E10: =(1*D8+2*D9+3*D10)/6 -> 3016609.3 | F10: =$J$6+$J$5*C10 -> 2492220.2
B11: ='Monthly Data'!D187 -> Jun-20 | C11: ='Monthly Data'!E187 -> 6 | D11: ='Monthly Data'!F187 -> 3937405 | E11: =(1*D9+2*D10+3*D11)/6 -> 3498474.7 | F11: =$J$6+$J$5*C11 -> 2521806.5
B12: ='Monthly Data'!D188 -> Jul-20 | C12: ='Monthly Data'!E188 -> 7 | D12: ='Monthly Data'!F188 -> 3236264 | E12: =(1*D10+2*D11+3*D12)/6 -> 3487415.5 | F12: =$J$6+$J$5*C12 -> 2551392.8
B13: ='Monthly Data'!D189 -> Aug-20 | C13: ='Monthly Data'!E189 -> 8 | D13: ='Monthly Data'!F189 -> 2978169 | E13: =(1*D11+2*D12+3*D13)/6 -> 3224073.3 | F13: =$J$6+$J$5*C13 -> 2580979.1
B14: ='Monthly Data'!D190 -> Sep-20 | C14: ='Monthly Data'!E190 -> 9 | D14: ='Monthly Data'!F190 -> 2944899 | E14: =(1*D12+2*D13+3*D14)/6 -> 3004549.8 | F14: =$J$6+$J$5*C14 -> 2610565.4
B15: ='Monthly Data'!D191 -> Oct-20 | C15: ='Monthly Data'!E191 -> 10 | D15: ='Monthly Data'!F191 -> 2574803 | E15: =(1*D13+2*D14+3*D15)/6 -> 2765396 | F15: =$J$6+$J$5*C15 -> 2640151.7
B16: ='Monthly Data'!D192 -> Nov-20 | C16: ='Monthly Data'!E192 -> 11 | D16: ='Monthly Data'!F192 -> 2560547 | E16: =(1*D14+2*D15+3*D16)/6 -> 2629357.7 | F16: =$J$6+$J$5*C16 -> 2669738
B17: ='Monthly Data'!D193 -> Dec-20 | C17: ='Monthly Data'!E193 -> 12 | D17: ='Monthly Data'!F193 -> 3445867 | E17: =(1*D15+2*D16+3*D17)/6 -> 3005583 | F17: =$J$6+$J$5*C17 -> 2699324.3
B18: ='Monthly Data'!D194 -> Jan-21 | C18: ='Monthly Data'!E194 -> 13 | D18: ='Monthly Data'!F194 -> 1583647 | E18: =(1*D16+2*D17+3*D18)/6 -> 2367203.7 | F18: =$J$6+$J$5*C18 -> 2728910.6
B19: ='Monthly Data'!D195 -> Feb-21 | C19: ='Monthly Data'!E195 -> 14 | D19: ='Monthly Data'!F195 -> 1604770 | E19: =(1*D17+2*D18+3*D19)/6 -> 1904578.5 | F19: =$J$6+$J$5*C19 -> 2758497
B20: ='Monthly Data'!D196 -> Mar-21 | C20: ='Monthly Data'!E196 -> 15 | D20: ='Monthly Data'!F196 -> 1842473 | E20: =(1*D18+2*D19+3*D20)/6 -> 1720101 | F20: =$J$6+$J$5*C20 -> 2788083.3
... B41: ='Monthly Data'!D217 -> Dec-22 | C41: ='Monthly Data'!E217 -> 36 | D41: ='Monthly Data'!F217 -> 4286506 | E41: =(1*D39+2*D40+3*D41)/6 -> 3776829.5 | F41: =$J$6+$J$5*C41 -> 3409395.8
B42: Jan-23 | C42: 37 | E42: =(1*D39+2*D40+3*D41)/6 -> 3776829.5 | F42: =$J$6+$J$5*C42 -> 3438982.1
B43: Feb-23 | C43: 38 | E43: =(1*D40+2*D41+3*E42)/6 -> 3870248.6 | F43: =$J$6+$J$5*C43 -> 3468568.4
B44: Mar-23 | C44: 39 | E44: =(1*D41+2*E42+3*E43)/6 -> 3908485.1 | F44: =$J$6+$J$5*C44 -> 3498154.7
B47: Preprocessing notes
B48: Computed as SUMIFS across the 5 titles per month on the Monthly Data sheet — a fully live aggregate.
B51: Interpretation & recommendation
B52: • Group total fell 23.3% in 2021 then rose 57.3% in 2022, finishing 20.7% above the 2020 starting level — genuine 3-year growth.
B53: • The 2021 dip shows up in all 5 titles individually, not just the total, which is what makes it a credible shared event (distribution/macro disruption) rather than noise in one title.
B54: • WMA forecasts continued Q1 2023 growth (more responsive to late-2022 momentum); the trendline forecast is flatter and more conservative — plan operations against WMA, budget commitments against the trendline.

Sheet Final Results
B2: Final Results — Forecasting & Trendline Module
B4: Consolidated view of all 5 titles plus the Group total. Full WMA tables, trendline stats and charts are on each corresponding Analysis sheet.
B6: Series | C6: 2020->2021 | D6: 2021->2022 | E6: 2020->2022 net | F6: Linear R² | G6: Q1'23 WMA (Jan/Feb/Mar)
B7: Outlook Business | C7: -14.3% | D7: 33.5% | E7: 14.4% | F7: 0.00 | G7: 767,389 / 807,385 / 822,576
B8: Outlook Hindi | C8: 7.8% | D8: 12.9% | E8: 21.7% | F8: 0.25 | G8: 444,645 / 462,184 / 470,163
B9: Outlook India | C9: -50.5% | D9: 188.1% | E9: 42.8% | F9: 0.27 | G9: 1,664,769 / 1,698,997 / 1,713,653
B10: Outlook Money | C10: -12.9% | D10: 20.6% | E10: 5.0% | F10: 0.13 | G10: 617,937 / 618,680 / 618,852
B11: Outlook Traveller | C11: -14.6% | D11: 16.9% | E11: -0.2% | F11: 0.05 | G11: 282,090 / 283,003 / 283,241
B12: Outlook Group (All Titles) | C12: -23.3% | D12: 57.3% | E12: 20.7% | F12: 0.17 | G12: 3,776,830 / 3,870,249 / 3,908,485
B14: Overall conclusion
B15: Every title shows the same 2021-dip / 2022-recovery shape; the Group total ends the 3-year window 20.7% above where it started. Growth is real but concentrated in the recovery, not a steady monthly climb (low linear R² across the board) — plan Q1 2023 operations against the more responsive WMA forecast, and budget/board commitments against the more conservative trendline forecast.
