Workbook

Sheet README
A1: Cash Flow Analysis Module — Analysis Workbook
A3: Prepared by: Aishwarya | Outlook Live Project Program — MBA Business Analytics
A5: The source file (BS_AND_PL_STATEMENTS.xlsx) contains a Balance Sheet and P&L for FY2020-FY2024
A6: but no Cash Flow Statement. A Cash Flow Statement (indirect method) was therefore DERIVED from the
A7: year-on-year changes in the Balance Sheet plus the P&L, for FY2021-FY2024 (FY2020 is the base year
A8: with no prior-year column to derive a change from).
A10: Data limitation, stated plainly: FY2021's Balance Sheet lumps all fixed assets into a single
A11: 'Tangible Assets' line, while every other year splits Tangible/Intangible/CWIP/Other separately.
A12: This distorts the capex approximation for FY2021 and FY2022 specifically. As a built-in check, the
A13: derived net cash change is reconciled against the actual change in the Cash & Cash Equivalents
A14: balance sheet line each year - FY2023's reconciliation is near-exact (an Rs 0.3 Cr gap), which
A15: validates the method; FY2021/FY2022's larger gaps are attributable to that classification break,
... A25: Final Results - headline numbers and interpretation in one place.

Sheet Raw Data (BS)
A1: BALANCE SHEET (Rs. Cr) | B1: FY2020 | C1: FY2021 | D1: FY2022 | E1: FY2023 | F1: FY2024
A2: BALANCE SHEET (in Rs. Cr.)
A3: EQUITIES AND LIABILITIES
A4: SHAREHOLDER'S FUNDS
A5: Equity Share Capital | B5: 46.11 | C5: 46.11 | D5: 46.11 | E5: 46.11 | F5: 46.1
A6: TOTAL SHARE CAPITAL | B6: 46.11 | C6: 46.11 | D6: 46.11 | E6: 46.11 | F6: 46.1
A7: Reserves and Surplus | B7: 1311.5 | C7: 1097.47 | D7: 1575.77 | E7: 1734.61 | F7: 1652.25
A8: TOTAL RESERVES AND SURPLUS | B8: 1311.5 | C8: 1097.47 | D8: 1575.77 | E8: 1734.61 | F8: 1652.25
A9: TOTAL SHAREHOLDERS FUNDS | B9: 1357.61 | C9: 1143.58 | D9: 1621.88 | E9: 1780.72 | F9: 1698.35
A10: NON-CURRENT LIABILITIES
A11: Long Term Borrowings | B11: 124.63 | C11: 91.2 | D11: 232.8 | E11: 5.7 | F11: 17.02
A12: Deferred Tax Liabilities [Net] | B12: 0 | C12: 0 | D12: 0 | E12: 0 | F12: 0
A13: Other Long Term Liabilities | B13: 83.64 | C13: 57.16 | D13: 30.38 | E13: 19.85 | F13: 17.99
A14: Long Term Provisions | B14: 2.91 | C14: 0 | D14: 2.13 | E14: 1.86 | F14: 1.19
A15: TOTAL NON-CURRENT LIABILITIES | B15: 211.18 | C15: 148.36 | D15: 265.31 | E15: 27.41 | F15: 36.2
A16: CURRENT LIABILITIES
A17: Short Term Borrowings | B17: 421.55 | C17: 450.5 | D17: 1087.1 | E17: 1050.18 | F17: 970.38
A18: Trade Payables | B18: 201.76 | C18: 171.03 | D18: 287.75 | E18: 248.87 | F18: 302.71
A19: Other Current Liabilities | B19: 529.19 | C19: 531.55 | D19: 444.72 | E19: 418.06 | F19: 387.04
A20: Short Term Provisions | B20: 4.53 | C20: 2.29 | D20: 5.07 | E20: 5.56 | F20: 22.97
A21: TOTAL CURRENT LIABILITIES | B21: 1157.03 | C21: 1155.37 | D21: 1824.64 | E21: 1722.67 | F21: 1683.1
A22: TOTAL CAPITAL AND LIABILITIES | B22: 2725.82 | C22: 2447.31 | D22: 3711.83 | E22: 3530.8 | F22: 3417.65
A23: ASSETS
A24: NON-CURRENT ASSETS
A25: Tangible Assets | B25: 410.83 | C25: 893.38 | D25: 340.83 | E25: 371.39 | F25: 424.53
A26: Intangible Assets | B26: 330.33 | C26: 0 | D26: 367.23 | E26: 401.66 | F26: 437.47
A27: Capital Work-In-Progress | B27: 29.41 | C27: 0 | D27: 29.37 | E27: 30.1 | F27: 32.52
A28: Other Assets | B28: 427.5 | C28: 0 | D28: 425.21 | E28: 439.39 | F28: 335.69
A29: FIXED ASSETS | B29: 1198.58 | C29: 893.38 | D29: 1162.84 | E29: 1242.83 | F29: 1230.81
A30: Non-Current Investments | B30: 588.5 | C30: 626.2 | D30: 903.61 | E30: 1310.65 | F30: 1488.38
A31: Deferred Tax Assets [Net] | B31: 26.61 | C31: 143.68 | D31: 49.26 | E31: 6.5 | F31: 12.77
A32: Long Term Loans And Advances | B32: 116.94 | C32: 226.4 | D32: 139.33 | E32: 124.22 | F32: 34.45
A33: Other Non-Current Assets | B33: 86.73 | C33: 70.6 | D33: 61.79 | E33: 49 | F33: 54.52
A34: TOTAL NON-CURRENT ASSETS | B34: 2017.36 | C34: 1960.26 | D34: 2316.83 | E34: 2733.2 | F34: 2820.93
A35: CURRENT ASSETS
A36: Current Investments | B36: 238.01 | C36: 132.91 | D36: 815.82 | E36: 323.4 | F36: 165.98
A37: Inventories | B37: 95.12 | C37: 88.02 | D37: 119.2 | E37: 77.16 | F37: 107.91
A38: Trade Receivables | B38: 259.72 | C38: 132.62 | D38: 252.43 | E38: 216.84 | F38: 177.05
A39: Cash And Cash Equivalents | B39: 47.36 | C39: 46.25 | D39: 120.25 | E39: 80.5 | F39: 65.91
A40: Short Term Loans And Advances | B40: 0 | C40: 0 | D40: 15.99 | E40: 15.99 | F40: 16.97
...

Sheet Raw Data (P&L)
A1: PROFIT & LOSS (Rs. Cr) | B1: FY2020 | C1: FY2021 | D1: FY2022 | E1: FY2023 | F1: FY2024
A2: PROFIT & LOSS ACCOUNT (in Rs. Cr.)
A3: INCOME
A4: REVENUE FROM OPERATIONS [GROSS] | B4: 1138.8 | C4: 528.1 | D4: 1290.65 | E4: 1373.26 | F4: 1418.89
A5: Less: Excise/Sevice Tax/Other Levies | B5: 0 | C5: 0 | D5: 0 | E5: 0 | F5: 0
A6: REVENUE FROM OPERATIONS [NET] | B6: 1138.8 | C6: 528.1 | D6: 1290.65 | E6: 1373.26 | F6: 1418.89
A7: TOTAL OPERATING REVENUES | B7: 1243.33 | C7: 528.1 | D7: 1301.73 | E7: 1385.46 | F7: 1432.04
A8: Other Income | B8: 126.61 | C8: 100.58 | D8: 145.1 | E8: 210.13 | F8: 156.89
A9: TOTAL REVENUE | B9: 1369.94 | C9: 628.68 | D9: 1446.83 | E9: 1595.59 | F9: 1588.93
A10: EXPENSES
A11: Cost Of Materials Consumed | B11: 286.38 | C11: 83.24 | D11: 376.47 | E11: 298.44 | F11: 351.51
A12: Operating And Direct Expenses | B12: 0 | C12: 0 | D12: 0 | E12: 0 | F12: 0
A13: Changes In Inventories Of FG,WIP And Stock-In Trade | B13: -1.75 | C13: 1.52 | D13: -0.24 | E13: 0.01 | F13: 0.05
A14: Employee Benefit Expenses | B14: 272.2 | C14: 179.81 | D14: 250.99 | E14: 252.44 | F14: 327.95
A15: Finance Costs | B15: 103.45 | C15: 45.87 | D15: 98.44 | E15: 69.6 | F15: 78.68
A16: Depreciation And Amortisation Expenses | B16: 113.45 | C16: 90.9 | D16: 82.69 | E16: 96.42 | F16: 97.47
A17: Other Expenses | B17: 581.31 | C17: 369.99 | D17: 698.38 | E17: 617.75 | F17: 669.08
A18: TOTAL EXPENSES | B18: 1355.04 | C18: 771.33 | D18: 1506.73 | E18: 1334.66 | F18: 1524.74
A19: PROFIT/LOSS BEFORE EXCEPTIONAL, EXTRAORDINARY ITEMS AND TAX | B19: 14.9 | C19: -142.65 | D19: -59.9 | E19: 260.93 | F19: 64.19
A20: Exceptional Items | B20: -270.78 | C20: 7.21 | D20: -112.11 | E20: -14.05 | F20: 0
A21: PROFIT/LOSS BEFORE TAX | B21: -255.88 | C21: -135.44 | D21: -172.01 | E21: 246.88 | F21: 64.19
A22: TAX EXPENSES-CONTINUED OPERATIONS
A23: Current Tax | B23: 5.7 | C23: -54.09 | D23: 4.26 | E23: 29.44 | F23: -8.25
A24: Less: MAT Credit Entitlement | B24: 0 | C24: 0 | D24: 0 | E24: 0 | F24: 0
A25: Deferred Tax | B25: 4.21 | C25: 0 | D25: -37.33 | E25: 6.28 | F25: 10.93
A26: Tax For Earlier Years | B26: 0 | C26: 0 | D26: 0 | E26: 0 | F26: 0
A27: TOTAL TAX EXPENSES | B27: 9.91 | C27: -54.09 | D27: -33.07 | E27: 35.72 | F27: 2.68
A28: PROFIT/LOSS AFTER TAX AND BEFORE EXTRAORDINARY ITEMS | B28: -265.79 | C28: -81.35 | D28: -138.94 | E28: 211.16 | F28: 61.51
A29: PROFIT/LOSS FROM CONTINUING OPERATIONS | B29: -265.79 | C29: -81.35 | D29: -138.94 | E29: 211.16 | F29: 61.51
A30: PROFIT/LOSS FOR THE PERIOD | B30: -265.79 | C30: -81.35 | D30: -138.94 | E30: 213.74 | F30: 61.51
A31: OTHER ADDITIONAL INFORMATION
A32: EARNINGS PER SHARE
A33: Basic EPS (Rs.) | B33: -11.53 | C33: -3.53 | D33: -5.97 | E33: 9.18 | F33: 2.64
A34: Diluted EPS (Rs.) | B34: -11.53 | C34: -3.53 | D34: -5.97 | E34: 9.18 | F34: 2.64
A35: VALUE OF IMPORTED AND INDIGENIOUS RAW MATERIALS STORES, SPARES AND LOOSE TOOLS
A36: Imported Raw Materials | B36: 0 | C36: 0 | D36: 0 | E36: 0 | F36: 0
A37: Indigenous Raw Materials | B37: 0 | C37: 0 | D37: 0 | E37: 0 | F37: 0
A38: STORES, SPARES AND LOOSE TOOLS
A39: Imported Stores And Spares | B39: 0 | C39: 0 | D39: 0 | E39: 0 | F39: 0
A40: Indigenous Stores And Spares | B40: 0 | C40: 0 | D40: 0 | E40: 0 | F40: 0
...

Sheet Derived Cash Flow Statement
B2: Derived Cash Flow Statement — Indirect Method (Rs. Cr)
B4: Derived from year-on-year Balance Sheet changes plus the P&L, since the source file contains no cash flow statement. All cells below are live formulas referencing the two Raw Data sheets.
B6: (Rs. Cr) | C6: FY2021 | D6: FY2022 | E6: FY2023 | F6: FY2024
B7: Cash Flow from Operating Activities (CFO)
B8: Profit Before Tax (PBT) | C8: ='Raw Data (P&L)'!$C$21 -> -135.44 | D8: ='Raw Data (P&L)'!$D$21 -> -172.01 | E8: ='Raw Data (P&L)'!$E$21 -> 246.88 | F8: ='Raw Data (P&L)'!$F$21 -> 64.19
B9: Add: Depreciation & Amortisation | C9: ='Raw Data (P&L)'!$C$16 -> 90.9 | D9: ='Raw Data (P&L)'!$D$16 -> 82.69 | E9: ='Raw Data (P&L)'!$E$16 -> 96.42 | F9: ='Raw Data (P&L)'!$F$16 -> 97.47
B10: Add: Finance Costs | C10: ='Raw Data (P&L)'!$C$15 -> 45.87 | D10: ='Raw Data (P&L)'!$D$15 -> 98.44 | E10: ='Raw Data (P&L)'!$E$15 -> 69.6 | F10: ='Raw Data (P&L)'!$F$15 -> 78.68
B11: Less: Other Income | C11: =-'Raw Data (P&L)'!$C$8 -> -100.58 | D11: =-'Raw Data (P&L)'!$D$8 -> -145.1 | E11: =-'Raw Data (P&L)'!$E$8 -> -210.13 | F11: =-'Raw Data (P&L)'!$F$8 -> -156.89
B12: Operating Profit before Working Capital Changes | C12: =SUM(C8:C11) -> -99.25 | D12: =SUM(D8:D11) -> -135.98 | E12: =SUM(E8:E11) -> 202.77 | F12: =SUM(F8:F11) -> 83.45
B13: (Increase)/Decrease in Inventories | C13: =-('Raw Data (BS)'!$C$37-'Raw Data (BS)'!$B$37) -> 7.1 | D13: =-('Raw Data (BS)'!$D$37-'Raw Data (BS)'!$C$37) -> -31.18 | E13: =-('Raw Data (BS)'!$E$37-'Raw Data (BS)'!$D$37) -> 42.04 | F13: =-('Raw Data (BS)'!$F$37-'Raw Data (BS)'!$E$37) -> -30.75
B14: (Increase)/Decrease in Trade Receivables | C14: =-('Raw Data (BS)'!$C$38-'Raw Data (BS)'!$B$38) -> 127.1 | D14: =-('Raw Data (BS)'!$D$38-'Raw Data (BS)'!$C$38) -> -119.81 | E14: =-('Raw Data (BS)'!$E$38-'Raw Data (BS)'!$D$38) -> 35.59 | F14: =-('Raw Data (BS)'!$F$38-'Raw Data (BS)'!$E$38) -> 39.79
B15: (Increase)/Decrease in Other Current Assets | C15: =-(('Raw Data (BS)'!$C$41+'Raw Data (BS)'!$C$40)-('Raw Data (BS)'!$B$41+'Raw Data (BS)'!$B$40)) -> -19 | D15: =-(('Raw Data (BS)'!$D$41+'Raw Data (BS)'!$D$40)-('Raw Data (BS)'!$C$41+'Raw Data (BS)'!$C$40)) -> -0.05 | E15: =-(('Raw Data (BS)'!$E$41+'Raw Data (BS)'!$E$40)-('Raw Data (BS)'!$D$41+'Raw Data (BS)'!$D$40)) -> -12.4 | F15: =-(('Raw Data (BS)'!$F$41+'Raw Data (BS)'!$F$40)-('Raw Data (BS)'!$E$41+'Raw Data (BS)'!$E$40)) -> 19.83
B16: Increase/(Decrease) in Trade Payables | C16: ='Raw Data (BS)'!$C$18-'Raw Data (BS)'!$B$18 -> -30.73 | D16: ='Raw Data (BS)'!$D$18-'Raw Data (BS)'!$C$18 -> 116.72 | E16: ='Raw Data (BS)'!$E$18-'Raw Data (BS)'!$D$18 -> -38.88 | F16: ='Raw Data (BS)'!$F$18-'Raw Data (BS)'!$E$18 -> 53.84
B17: Increase/(Decrease) in Other Current Liabilities | C17: ='Raw Data (BS)'!$C$19-'Raw Data (BS)'!$B$19 -> 2.36 | D17: ='Raw Data (BS)'!$D$19-'Raw Data (BS)'!$C$19 -> -86.83 | E17: ='Raw Data (BS)'!$E$19-'Raw Data (BS)'!$D$19 -> -26.66 | F17: ='Raw Data (BS)'!$F$19-'Raw Data (BS)'!$E$19 -> -31.02
B18: Increase/(Decrease) in Provisions (ST+LT) | C18: =('Raw Data (BS)'!$C$20-'Raw Data (BS)'!$B$20)+('Raw Data (BS)'!$C$14-'Raw Data (BS)'!$B$14) -> -5.15 | D18: =('Raw Data (BS)'!$D$20-'Raw Data (BS)'!$C$20)+('Raw Data (BS)'!$D$14-'Raw Data (BS)'!$C$14) -> 4.91 | E18: =('Raw Data (BS)'!$E$20-'Raw Data (BS)'!$D$20)+('Raw Data (BS)'!$E$14-'Raw Data (BS)'!$D$14) -> 0.22 | F18: =('Raw Data (BS)'!$F$20-'Raw Data (BS)'!$E$20)+('Raw Data (BS)'!$F$14-'Raw Data (BS)'!$E$14) -> 16.74
B19: Increase/(Decrease) in Other LT Liabilities | C19: ='Raw Data (BS)'!$C$13-'Raw Data (BS)'!$B$13 -> -26.48 | D19: ='Raw Data (BS)'!$D$13-'Raw Data (BS)'!$C$13 -> -26.78 | E19: ='Raw Data (BS)'!$E$13-'Raw Data (BS)'!$D$13 -> -10.53 | F19: ='Raw Data (BS)'!$F$13-'Raw Data (BS)'!$E$13 -> -1.86
B20: Cash Generated from Operations | C20: =SUM(C12:C19) -> -44.05 | D20: =SUM(D12:D19) -> -279 | E20: =SUM(E12:E19) -> 192.15 | F20: =SUM(F12:F19) -> 150.02
B21: Less: Taxes Paid | C21: =-'Raw Data (P&L)'!$C$27 -> 54.09 | D21: =-'Raw Data (P&L)'!$D$27 -> 33.07 | E21: =-'Raw Data (P&L)'!$E$27 -> -35.72 | F21: =-'Raw Data (P&L)'!$F$27 -> -2.68
B22: Net Cash Flow from Operating Activities (CFO) | C22: =C20+C21 -> 10.04 | D22: =D20+D21 -> -245.93 | E22: =E20+E21 -> 156.43 | F22: =F20+F21 -> 147.34
B24: Cash Flow from Investing Activities (CFI)
B25: Capital Expenditure (approx., net FA change + depreciation) | C25: =-(('Raw Data (BS)'!$C$29-'Raw Data (BS)'!$B$29)+'Raw Data (P&L)'!$C$16) -> 214.3 | D25: =-(('Raw Data (BS)'!$D$29-'Raw Data (BS)'!$C$29)+'Raw Data (P&L)'!$D$16) -> -352.15 | E25: =-(('Raw Data (BS)'!$E$29-'Raw Data (BS)'!$D$29)+'Raw Data (P&L)'!$E$16) -> -176.41 | F25: =-(('Raw Data (BS)'!$F$29-'Raw Data (BS)'!$E$29)+'Raw Data (P&L)'!$F$16) -> -85.45
B26: (Investment in)/Proceeds from Non-Current Investments | C26: =-('Raw Data (BS)'!$C$30-'Raw Data (BS)'!$B$30) -> -37.7 | D26: =-('Raw Data (BS)'!$D$30-'Raw Data (BS)'!$C$30) -> -277.41 | E26: =-('Raw Data (BS)'!$E$30-'Raw Data (BS)'!$D$30) -> -407.04 | F26: =-('Raw Data (BS)'!$F$30-'Raw Data (BS)'!$E$30) -> -177.73
B27: (Investment in)/Proceeds from Current Investments | C27: =-('Raw Data (BS)'!$C$36-'Raw Data (BS)'!$B$36) -> 105.1 | D27: =-('Raw Data (BS)'!$D$36-'Raw Data (BS)'!$C$36) -> -682.91 | E27: =-('Raw Data (BS)'!$E$36-'Raw Data (BS)'!$D$36) -> 492.42 | F27: =-('Raw Data (BS)'!$F$36-'Raw Data (BS)'!$E$36) -> 157.42
B28: (Increase)/Decrease in LT Loans & Advances | C28: =-('Raw Data (BS)'!$C$32-'Raw Data (BS)'!$B$32) -> -109.46 | D28: =-('Raw Data (BS)'!$D$32-'Raw Data (BS)'!$C$32) -> 87.07 | E28: =-('Raw Data (BS)'!$E$32-'Raw Data (BS)'!$D$32) -> 15.11 | F28: =-('Raw Data (BS)'!$F$32-'Raw Data (BS)'!$E$32) -> 89.77
B29: (Increase)/Decrease in Other Non-Current Assets | C29: =-('Raw Data (BS)'!$C$33-'Raw Data (BS)'!$B$33) -> 16.13 | D29: =-('Raw Data (BS)'!$D$33-'Raw Data (BS)'!$C$33) -> 8.81 | E29: =-('Raw Data (BS)'!$E$33-'Raw Data (BS)'!$D$33) -> 12.79 | F29: =-('Raw Data (BS)'!$F$33-'Raw Data (BS)'!$E$33) -> -5.52
B30: Add: Other Income (investment income received) | C30: ='Raw Data (P&L)'!$C$8 -> 100.58 | D30: ='Raw Data (P&L)'!$D$8 -> 145.1 | E30: ='Raw Data (P&L)'!$E$8 -> 210.13 | F30: ='Raw Data (P&L)'!$F$8 -> 156.89
B31: Net Cash Flow from Investing Activities (CFI) | C31: =SUM(C25:C30) -> 288.95 | D31: =SUM(D25:D30) -> -1071.49 | E31: =SUM(E25:E30) -> 147 | F31: =SUM(F25:F30) -> 135.38
B33: Cash Flow from Financing Activities (CFF)
B34: Proceeds/(Repayment) of Long Term Borrowings | C34: ='Raw Data (BS)'!$C$11-'Raw Data (BS)'!$B$11 -> -33.43 | D34: ='Raw Data (BS)'!$D$11-'Raw Data (BS)'!$C$11 -> 141.6 | E34: ='Raw Data (BS)'!$E$11-'Raw Data (BS)'!$D$11 -> -227.1 | F34: ='Raw Data (BS)'!$F$11-'Raw Data (BS)'!$E$11 -> 11.32
B35: Proceeds/(Repayment) of Short Term Borrowings | C35: ='Raw Data (BS)'!$C$17-'Raw Data (BS)'!$B$17 -> 28.95 | D35: ='Raw Data (BS)'!$D$17-'Raw Data (BS)'!$C$17 -> 636.6 | E35: ='Raw Data (BS)'!$E$17-'Raw Data (BS)'!$D$17 -> -36.92 | F35: ='Raw Data (BS)'!$F$17-'Raw Data (BS)'!$E$17 -> -79.8
B36: Change in Equity Share Capital | C36: ='Raw Data (BS)'!$C$5-'Raw Data (BS)'!$B$5 -> 0 | D36: ='Raw Data (BS)'!$D$5-'Raw Data (BS)'!$C$5 -> 0 | E36: ='Raw Data (BS)'!$E$5-'Raw Data (BS)'!$D$5 -> 0 | F36: ='Raw Data (BS)'!$F$5-'Raw Data (BS)'!$E$5 -> -0.01
B37: Less: Finance Costs (interest paid) | C37: =-'Raw Data (P&L)'!$C$15 -> -45.87 | D37: =-'Raw Data (P&L)'!$D$15 -> -98.44 | E37: =-'Raw Data (P&L)'!$E$15 -> -69.6 | F37: =-'Raw Data (P&L)'!$F$15 -> -78.68
B38: Less: Dividend Paid (incl. dividend tax) | C38: =-('Raw Data (P&L)'!$C$42+'Raw Data (P&L)'!$C$43) -> 0 | D38: =-('Raw Data (P&L)'!$D$42+'Raw Data (P&L)'!$D$43) -> -9.88 | E38: =-('Raw Data (P&L)'!$E$42+'Raw Data (P&L)'!$E$43) -> -9.87 | F38: =-('Raw Data (P&L)'!$F$42+'Raw Data (P&L)'!$F$43) -> -9.87
B39: Net Cash Flow from Financing Activities (CFF) | C39: =SUM(C34:C38) -> -50.35 | D39: =SUM(D34:D38) -> 669.88 | E39: =SUM(E34:E38) -> -343.49 | F39: =SUM(F34:F38) -> -157.04
B41: Reconciliation
B42: Net Change in Cash (Derived: CFO+CFI+CFF) | C42: =C22+C31+C39 -> 248.64 | D42: =D22+D31+D39 -> -647.54 | E42: =E22+E31+E39 -> -40.06 | F42: =F22+F31+F39 -> 125.68
B43: Actual Change in Cash & Cash Equivalents (from BS) | C43: ='Raw Data (BS)'!$C$39-'Raw Data (BS)'!$B$39 -> -1.11 | D43: ='Raw Data (BS)'!$D$39-'Raw Data (BS)'!$C$39 -> 74 | E43: ='Raw Data (BS)'!$E$39-'Raw Data (BS)'!$D$39 -> -39.75 | F43: ='Raw Data (BS)'!$F$39-'Raw Data (BS)'!$E$39 -> -14.59
B44: Reconciliation Gap | C44: =C42-C43 -> 249.75 | D44: =D42-D43 -> -721.54 | E44: =E42-E43 -> -0.31 | F44: =F42-F43 -> 140.27
B46: Free Cash Flow (CFO - Capex) | C46: =C22+C25 -> 224.34 | D46: =D22+D25 -> -598.08 | E46: =E22+E25 -> -19.98 | F46: =F22+F25 -> 61.89

Sheet Ratio Analysis
B2: Cash Flow Ratio Analysis
B5: (Rs. Cr unless stated) | C5: FY2021 | D5: FY2022 | E5: FY2023 | F5: FY2024
B6: CFO (Rs. Cr) | C6: ='Derived Cash Flow Statement'!C22 -> 10.04 | D6: ='Derived Cash Flow Statement'!D22 -> -245.93 | E6: ='Derived Cash Flow Statement'!E22 -> 156.43 | F6: ='Derived Cash Flow Statement'!F22 -> 147.34
B7: Free Cash Flow (Rs. Cr) | C7: ='Derived Cash Flow Statement'!C46 -> 224.34 | D7: ='Derived Cash Flow Statement'!D46 -> -598.08 | E7: ='Derived Cash Flow Statement'!E46 -> -19.98 | F7: ='Derived Cash Flow Statement'!F46 -> 61.89
B8: Operating Cash Flow to Sales (CFO / Total Operating Revenue) | C8: ='Derived Cash Flow Statement'!C22/'Raw Data (P&L)'!$C$7 -> 0.019011551 | D8: ='Derived Cash Flow Statement'!D22/'Raw Data (P&L)'!$D$7 -> -0.18892551 | E8: ='Derived Cash Flow Statement'!E22/'Raw Data (P&L)'!$E$7 -> 0.11290835 | F8: ='Derived Cash Flow Statement'!F22/'Raw Data (P&L)'!$F$7 -> 0.10288819
B9: Cash Flow Adequacy (CFO / (Capex + Dividends)) | C9: ='Derived Cash Flow Statement'!C22/(-'Derived Cash Flow Statement'!C25+'Raw Data (P&L)'!$C$42+'Raw Data (P&L)'!$C$43) -> -0.04685021 | D9: ='Derived Cash Flow Statement'!D22/(-'Derived Cash Flow Statement'!D25+'Raw Data (P&L)'!$D$42+'Raw Data (P&L)'!$D$43) -> -0.67930834 | E9: ='Derived Cash Flow Statement'!E22/(-'Derived Cash Flow Statement'!E25+'Raw Data (P&L)'!$E$42+'Raw Data (P&L)'!$E$43) -> 0.83975735 | F9: ='Derived Cash Flow Statement'!F22/(-'Derived Cash Flow Statement'!F25+'Raw Data (P&L)'!$F$42+'Raw Data (P&L)'!$F$43) -> 1.5457407
B10: CFO to Total Debt (CFO / (LT + ST Borrowings)) | C10: ='Derived Cash Flow Statement'!C22/('Raw Data (BS)'!$C$11+'Raw Data (BS)'!$C$17) -> 0.018534244 | D10: ='Derived Cash Flow Statement'!D22/('Raw Data (BS)'!$D$11+'Raw Data (BS)'!$D$17) -> -0.18632472 | E10: ='Derived Cash Flow Statement'!E22/('Raw Data (BS)'!$E$11+'Raw Data (BS)'!$E$17) -> 0.14815131 | F10: ='Derived Cash Flow Statement'!F22/('Raw Data (BS)'!$F$11+'Raw Data (BS)'!$F$17) -> 0.14922017
B11: Cash flow classification | C11: =IF('Derived Cash Flow Statement'!C22>0,"CFO Positive","CFO Negative") -> CFO Positive | D11: =IF('Derived Cash Flow Statement'!D22>0,"CFO Positive","CFO Negative") -> CFO Negative | E11: =IF('Derived Cash Flow Statement'!E22>0,"CFO Positive","CFO Negative") -> CFO Positive | F11: =IF('Derived Cash Flow Statement'!F22>0,"CFO Positive","CFO Negative") -> CFO Positive
B13: Interpretation
B14: CFO swings from marginally positive (FY2021) to sharply negative (FY2022, the same year non-current and current investments both roughly doubled) before stabilising positive in FY2023-24. Free Cash Flow is negative in 2 of the 4 derived years, meaning operating cash generation alone did not cover capital expenditure in those years, and the gap was bridged by financing activity (borrowings) rather than internally generated cash - a genuine, if data-limited, signal of financial strain in FY2022 specifically.

Sheet Secondary Research
B2: Secondary Research — Sector Cash Flow Comparison
B4: Published cash flow figures (most recent available FY) for 2 companies each in FMCG, FMCD, and BFSI, sourced externally (not derived from this project's own data) to benchmark financial stability patterns across sectors.
B7: Company (Sector) | C7: CFO (Rs. Cr) | D7: CFI (Rs. Cr) | E7: CFF (Rs. Cr) | F7: FCF (Rs. Cr)
B8: Hindustan Unilever (FY24) (FMCG) | C8: 14884 | D8: -5324 | E8: -10034 | F8: 13992
B9: Nestle India (FY24) (FMCG) | C9: 4340 | D9: -1404 | E9: -3133 | F9: 2458
B10: Voltas (FY24) (FMCD) | C10: 762 | D10: -522 | E10: -116 | F10: 468
B11: Havells India (FY24) (FMCD) | C11: 2096 | D11: -1765 | E11: -526 | F11: 1310
B12: Bajaj Finance (FY24) (BFSI) | C12: 19992 | D12: -98282 | E12: 82415 | F12: 18954
B32: Sector notes
B33: FMCG (HUL, Nestle India): both show strongly positive CFO well in excess of capex, and negative CFI/CFF driven by disciplined reinvestment and consistent dividend payout - the textbook profile of a mature, cash-generative sector.
B34: FMCD (Voltas, Havells): positive but thinner CFO relative to revenue than FMCG, with capex-driven negative CFI reflecting ongoing manufacturing capacity investment - a capital-intensive but still self-funding profile.
B35: BFSI (Bajaj Finance): CFO and CFI are structurally different from non-financial sectors - loan disbursement growth is treated as an operating/investing outflow, funded by a large positive CFF (fresh borrowings). A negative CFO or CFI here does not signal distress the way it would for a manufacturer; it reflects balance-sheet growth financed by fresh capital, and must be read against loan-book growth and asset quality, not against FCF alone.

Sheet Final Results
B2: Final Results — Cash Flow Analysis Module
B5: Metric | C5: FY2021 | D5: FY2022 | E5: FY2023 | F5: FY2024
B6: CFO | C6: ='Derived Cash Flow Statement'!C22 -> 10.04 | D6: ='Derived Cash Flow Statement'!D22 -> -245.93 | E6: ='Derived Cash Flow Statement'!E22 -> 156.43 | F6: ='Derived Cash Flow Statement'!F22 -> 147.34
B7: CFI | C7: ='Derived Cash Flow Statement'!C31 -> 288.95 | D7: ='Derived Cash Flow Statement'!D31 -> -1071.49 | E7: ='Derived Cash Flow Statement'!E31 -> 147 | F7: ='Derived Cash Flow Statement'!F31 -> 135.38
B8: CFF | C8: ='Derived Cash Flow Statement'!C39 -> -50.35 | D8: ='Derived Cash Flow Statement'!D39 -> 669.88 | E8: ='Derived Cash Flow Statement'!E39 -> -343.49 | F8: ='Derived Cash Flow Statement'!F39 -> -157.04
B9: Free Cash Flow | C9: ='Derived Cash Flow Statement'!C46 -> 224.34 | D9: ='Derived Cash Flow Statement'!D46 -> -598.08 | E9: ='Derived Cash Flow Statement'!E46 -> -19.98 | F9: ='Derived Cash Flow Statement'!F46 -> 61.89
B10: Reconciliation gap vs. actual cash change | C10: ='Derived Cash Flow Statement'!C44 -> 249.75 | D10: ='Derived Cash Flow Statement'!D44 -> -721.54 | E10: ='Derived Cash Flow Statement'!E44 -> -0.31 | F10: ='Derived Cash Flow Statement'!F44 -> 140.27
B12: Overall assessment
B13: The company's derived cash flow position tells a clear story of financial stress followed by stabilisation: FY2021 was a low-CFO, high-CFI-inflow year (asset disposals/reclassification); FY2022 shows the sharpest strain (CFO -Rs 245.9 Cr, FCF -Rs 598.1 Cr) coinciding with a large build-up in investments, funded by a Rs 669.9 Cr financing inflow; FY2023-24 show CFO recovering to a consistent Rs 147-156 Cr, with FCF returning to roughly break-even/positive. Against the FMCG/FMCD secondary-research benchmarks, this company's cash generation is far more volatile year-to-year than the mature FMCG peers, and its FY2022 dependence on financing inflows to cover an operating and investing cash shortfall is the single clearest financial-stability flag in this analysis.
